try:
    raise Exception("hello")
except:
    print("Caught the exception!")


